<?xml version="1.0"?>

<robot name="robot_c">

  <!-- Color of materials -->
  <material name="Blue">
    <color rgba="0 0.4 0.8 1"/>
  </material>
  <material name="Red">
    <color rgba="1 0 0 1"/>
  </material>
  <material name="Green">
    <color rgba="0 1 0 1"/>
  </material>
  <material name="Yellow">
    <color rgba="1 1 0 1"/>
  </material>
  <material name="White">
    <color rgba="1.1 1.1 1.1 1"/>
  </material>
  <material name="Black">
    <color rgba="0.1 0.1 0.1 1"/>
  </material>
  <material name="Grey">
        <color rgba="0.5 0.5 0.5 1.0"/>
  </material>

  <link name="base_link">
        <visual>
            <geometry>
                <box size="0.8 0.8 0.8"/>
            </geometry>
            <origin rpy="0 0 0" xyz="0 0 0"/>
            <material name="Blue" />
        </visual>
        <collision>
            <geometry>
                <box size="0.8 0.8 0.8"/>
            </geometry>
            <origin rpy="0 0 0" xyz="0 0 0"/>
            <material name="Blue" />
        </collision>
        <inertial>
            <mass value="3" />
            <inertia ixx="6.905" ixy="0.82" ixz="0.0" iyy="3.99" iyz="0.0" izz="6.58" />
        </inertial>
    </link>

    <joint name="base-0_joint" type="revolute">
        <parent link="base_link"/>
        <child link="0_link"/>
        <origin rpy="0 0 1.5708" xyz="-0.125 0 0"/>
        <axis xyz="0 1 0 " />
        <limit effort="300" velocity="0.1" lower="-1.5" upper="1.9"/>
        <dynamics damping="50" friction="1"/>
    </joint>

    <link name="0_link">
        <visual>
            <geometry>
                <mesh filename="package://lab2/manorobot/hombro1v3.stl"
                 scale="0.08 0.08 0.08" />
            </geometry>
            <origin rpy="0 -1.5708 0" xyz="0 0.275 0"/>
            <material name="Black" />
        </visual>
        <collision>
            <geometry>
                <mesh filename="package://lab2/manorobot/hombro1v3.stl"
                 scale="0.08 0.08 0.08" />
            </geometry>
            <origin rpy="0 -1.5708 0" xyz="0 0.275 0"/>
            <material name="Black" />
        </collision>
        <inertial>
         <mass value="1.05" />
         <inertia ixx="6.905" ixy="0.82" ixz="0.0" iyy="3.99" iyz="0.0" izz="6.58" />
        </inertial>
    </link>
    <gazebo reference="0_link">
        <material>Gazebo/Black</material>
    </gazebo>

    <joint name="0-1_joint" type="revolute">
        <parent link="0_link"/>
        <child link="1_link"/>
        <origin rpy="0 0 0" xyz="0 0.55 0" />
        <axis xyz="0 0 1" />
        <limit effort="300" velocity="0.1" lower="-1" upper="1"/>
        <dynamics damping="50" friction="1"/>
    </joint>

    <link name="1_link">
        <visual>
            <geometry>
               <mesh filename="package://lab2/manorobot/hombro2v6.stl"
                 scale="0.08 0.08 0.08" />
            </geometry>
            <origin rpy="0 -4.71239 3.1415" xyz="0 1 0"/>
            <material name="White" />
        </visual>
        <collision>
            <geometry>
                <mesh filename="package://lab2/manorobot/hombro2v6.stl"
                 scale="0.08 0.08 0.08"/>
            </geometry>
            <origin rpy="0 -4.71239 3.1415" xyz="0 1 0"/>
            <material name="White"/>
        </collision>
        <inertial>
         <mass value="1.553" />
         <inertia ixx="19.69" ixy="2.25" ixz="0.40" iyy="6.09" iyz="-1.97" izz="19.58" />
        </inertial>
    </link>
    <gazebo reference="1_link">
        <material>Gazebo/White</material>
    </gazebo>

    <joint name="1-2_joint" type="revolute">
        <parent link="1_link"/>
        <child link="2_link"/>
        <origin rpy="0 0 0" xyz="0 0.68 0"/>
        <axis xyz="1 0 0" />
        <limit effort="300" velocity="0.1" lower="-1.75" upper="1.75"/>
        <dynamics damping="50" friction="1"/>
    </joint>

    <link name="2_link">
        <visual>
            <geometry>
                <mesh filename="package://lab2/manorobot/brazo1v2.stl"
                    scale="0.08 0.08 0.08" />
            </geometry>
            <origin rpy="0 3.1415 3.1415" xyz="0 1.8 0"/>
            <material name="Grey" />
        </visual>
        <collision>
            <geometry>
                <mesh filename="package://lab2/manorobot/brazo1v2.stl"
                    scale="0.08 0.08 0.08" />
            </geometry>
            <origin rpy="0 3.1415 3.1415" xyz="0 1.8 0"/>
            <material name="Grey" />
        </collision>
        <inertial>
         <mass value="3.995" />
         <inertia ixx="89.92" ixy="61.25" ixz="10.30" iyy="71.41" iyz="-12.32" izz="141.58" />
        </inertial>
    </link>
    <gazebo reference="2_link">
        <material>Gazebo/Grey</material>
    </gazebo>


    <joint name="2-4_joint" type="revolute">
        <parent link="2_link"/>
        <child link="4_link"/>
        <origin rpy="0 0 0" xyz="0 1.6 0"/>
        <axis xyz="1 0 0" />
        <limit effort="300" velocity="0.1" lower="-1.1" upper="1.85"/>
        <dynamics damping="50" friction="1"/> 
    </joint>

    <link name="4_link">
        <visual>
            <geometry>
                <mesh filename="package://lab2/manorobot/antebrazo1v3.stl"
                    scale="0.08 0.08 0.08" />
            </geometry>
            <origin rpy="3.1415 0 0" xyz="0 1.7 0"/>
            <material name="White" />
        </visual>
        <collision>
            <geometry>
                <mesh filename="package://lab2/manorobot/antebrazo1v3.stl"
                    scale="0.08 0.08 0.08" />
            </geometry>
            <origin rpy="1.5708 0 0" xyz="0 1.7 0"/>
            <material name="White" />
        </collision>
        <inertial>
            <mass value="4.673" />
            <inertia ixx="196.77" ixy="18.68" ixz="4.70" iyy="33.48" iyz="-41.77" izz="188.74" />
        </inertial>
    </link>
    <gazebo reference="4_link">
        <material>Gazebo/White</material>
    </gazebo>

    <joint name="4-5_joint" type="revolute">
        <parent link="4_link"/>
        <child link="5_link"/>
        <origin rpy="0 0 0" xyz="0 1.6 0"/>
        <axis xyz="0 1 0" />
        <limit effort="300" velocity="0.1" lower="-1.15" upper="1.15"/>
        <dynamics damping="50" friction="1"/>
    </joint>

    <link name="5_link">
        <visual>
        <geometry>
            <cylinder length="0.4" radius="0.25"/>
        </geometry>
        <origin rpy="1.5708 0 0" xyz="0 0 0"/>
        <material name="Black" />
        </visual>
        <collision>
            <geometry>
                <cylinder length="0.4" radius="0.25"/>
            </geometry>
            <origin rpy="1.5708 0 0" xyz="0 0 0"/>
            <material name="Black" />
        </collision>
        <inertial>
         <mass value="0.875" />
         <inertia ixx="5.27" ixy="-22.62" ixz="-15.65" iyy="2.96" iyz="-0.448" izz="4.72" />
        </inertial>
    </link>
    <gazebo reference="5_link">
        <material>Gazebo/Black</material>
    </gazebo>

    <joint name="5-6_joint" type="revolute">
        <parent link="5_link"/>
        <child link="mesh_6_link"/>
        <origin rpy="0 0 0" xyz="0 0.2 0"/>
        <axis xyz="0 0 1" />
        <limit effort="300" velocity="0.1" lower="-1.25" upper="1.25"/>
        <dynamics damping="50" friction="1"/>
    </joint>
    

    <link name="mesh_6_link">
        <inertial>
            <origin rpy="0 0 0" xyz="0 0.275 0"/>
            <mass value="1.17563" />
            <inertia ixx="0.3615" ixy="0" ixz="-0.00681" iyy="0.4962" iyz="-0" izz="0.49" />
        </inertial>

        <visual>
            <origin rpy="3.1416 1.5708 0" xyz="0 0.275 0"/>
            <geometry>
                <mesh filename="package://lab2/manorobot/mano.dae"
                 scale="0.01 0.01 0.01" />
            </geometry>
        </visual>
        <collision>
            <origin rpy="0 0 0" xyz="0 0.275 0"/>
            <geometry>
                <mesh filename="package://lab2/manorobot/mano.dae"
                 scale="0.01 0.01 0.01" />
            </geometry>
        </collision>
   </link>
   
       
    <!-- Transmissions-->
    <transmission name="tran1">
        <type>transmission_interface/SimpleTransmission</type>
        <joint name="base-0_joint">
        <hardwareInterface>hardware_interface/EffortJointInterface</hardwareInterface>
        </joint>
        <actuator name="motor1">
        <hardwareInterface>hardware_interface/EffortJointInterface</hardwareInterface>
        <mechanicalReduction>1</mechanicalReduction>
        </actuator>
    </transmission>

    <transmission name="tran2">
        <type>transmission_interface/SimpleTransmission</type>
        <joint name="0-1_joint">
        <hardwareInterface>hardware_interface/EffortJointInterface</hardwareInterface>
        </joint>
        <actuator name="motor2">
        <hardwareInterface>hardware_interface/EffortJointInterface</hardwareInterface>
        <mechanicalReduction>1</mechanicalReduction>
        </actuator>
    </transmission>

    <transmission name="tran3">
        <type>transmission_interface/SimpleTransmission</type>
        <joint name="1-2_joint">
        <hardwareInterface>hardware_interface/EffortJointInterface</hardwareInterface>
        </joint>
        <actuator name="motor3">
        <hardwareInterface>hardware_interface/EffortJointInterface</hardwareInterface>
        <mechanicalReduction>1</mechanicalReduction>
        </actuator>
    </transmission>

    <transmission name="tran4">
        <type>transmission_interface/SimpleTransmission</type>
        <joint name="2-4_joint">
        <hardwareInterface>hardware_interface/EffortJointInterface</hardwareInterface>
        </joint>
        <actuator name="motor4">
        <hardwareInterface>hardware_interface/EffortJointInterface</hardwareInterface>
        <mechanicalReduction>1</mechanicalReduction>
        </actuator>
    </transmission>

    <transmission name="tran5">
        <type>transmission_interface/SimpleTransmission</type>
        <joint name="4-5_joint">
        <hardwareInterface>hardware_interface/EffortJointInterface</hardwareInterface>
        </joint>
        <actuator name="motor5">
        <hardwareInterface>hardware_interface/EffortJointInterface</hardwareInterface>
        <mechanicalReduction>1</mechanicalReduction>
        </actuator>
    </transmission>

    <transmission name="tran6">
        <type>transmission_interface/SimpleTransmission</type>
        <joint name="5-6_joint">
        <hardwareInterface>hardware_interface/EffortJointInterface</hardwareInterface>
        </joint>
        <actuator name="motor6">
        <hardwareInterface>hardware_interface/EffortJointInterface</hardwareInterface>
        <mechanicalReduction>1</mechanicalReduction>
        </actuator>
    </transmission>
    
    <gazebo reference="base-0_joint">
        <selfCollide>true</selfCollide>
    </gazebo>
    <gazebo reference="0-1_joint">
        <selfCollide>true</selfCollide>
    </gazebo>
    <gazebo reference="1-2_joint">
        <selfCollide>true</selfCollide>
    </gazebo>
    <gazebo reference="2-4_joint">
        <selfCollide>true</selfCollide>
    </gazebo>
    <gazebo reference="4-5_joint">
        <selfCollide>true</selfCollide>
    </gazebo>
    <gazebo reference="5-6_joint">
        <selfCollide>true</selfCollide>
    </gazebo>
    
        <!-- ROS base_link to UR 'Base' Coordinates transform -->
    <link name="base"/>
    <joint name="base_link-base_fixed_joint" type="fixed">
        <!-- NOTE: this rotation is only needed as long as base_link itself is
                    not corrected wrt the real robot (ie: rotated over 180
                    degrees)
        -->
        <origin rpy="0 0 1.5708" xyz="0 0 0"/>
        <parent link="base_link"/>
        <child link="base"/>
    </joint>
    
    <!-- <link name="world"/> -->
    <link name="world">
        <inertial>
        <mass value="0.0000001"/>
        <origin rpy="0 0 0" xyz="0.0 0.0 0.0"/>
        <inertia ixx="0.0000001" ixy="0.0" ixz="0.0" iyy="0.0000001" iyz="0.0" izz="0.0000001"/>
        </inertial>
    </link>
        
    <joint name="world_joint" type="fixed">
        <parent link="world"/>
        <child link="base_link"/>
        <origin rpy="0.0 0.0 0.0" xyz="0.0 0.0 0.0"/>
    </joint>


</robot>
